Workbook

Sheet Cover
B2: Integrated FP&A Planning & Forecast Model
B3: Rukmini KS — Illustrative IT Services Company (For demonstration)
B5: Prepared by: | C5: Rukmini KS
B6: Model date: | C6: 46285
B7: Portfolio Project | C7: 3-Year Driver-Based Financial Model
B8: Currency | C8: ₹ million unless otherwise stated
B9: Historical Period | C9: Jan-2025 to Dec-2026
B10: Forecast Period | C10: Jan-2027 to Dec-2027
B11: Model Purpose | C11: Revenue, headcount, opex, P&L, variance and scenario planning
B12: Model Logic | C12: Billable HC × utilization × working hours × billing rate
B13: Budget Logic | C13: Independent headcount, utilization, rate and cost assumptions
B14: Model Checks | C14: Reconciliations included on the Checks sheet
B15: Portfolio Note | C15: All data is fictional and created for demonstration purposes.
B17: How to use | C17: Select Base, Upside or Downside in Assumptions!B3. All forecast schedules, P&L and Executive Summary update automatically.

Sheet Assumptions
A1: Model Assumptions & Controls
A3: Active Scenario | B3: Base | C3: Select Base / Upside / Downside
A5: Active Scenario Drivers | B5: Value | C5: Unit | D5: Source / Note
A6: Utilization Change | B6: =INDEX(Scenarios!$B$4:$B$6,MATCH($B$3,Scenarios!$A$4:$A$6,0)) -> 0 | C6: percentage points | D6: Selected from Scenarios
A7: Billing Rate Growth | B7: =INDEX(Scenarios!$C$4:$C$6,MATCH($B$3,Scenarios!$A$4:$A$6,0)) -> 0.05 | C7: % | D7: Selected from Scenarios
A8: Salary Inflation | B8: =INDEX(Scenarios!$D$4:$D$6,MATCH($B$3,Scenarios!$A$4:$A$6,0)) -> 0.06 | C8: % | D8: Selected from Scenarios
A9: Other Opex Growth | B9: =INDEX(Scenarios!$E$4:$E$6,MATCH($B$3,Scenarios!$A$4:$A$6,0)) -> 0.05 | C9: % | D9: Selected from Scenarios
A10: Annual HC Growth | B10: =INDEX(Scenarios!$F$4:$F$6,MATCH($B$3,Scenarios!$A$4:$A$6,0)) -> 0.04 | C10: % | D10: Selected from Scenarios
A12: Business Unit | B12: Opening HC | C12: Billable % | D12: Base Utilization | E12: Billing Rate (₹/hr) | F12: Avg Monthly Salary (₹m) | G12: Software / HC (₹m)
A13: Cloud Services | B13: 145 | C13: 0.82 | D13: 0.78 | E13: 2250 | F13: 0.115 | G13: 0.01
A14: Data & Analytics | B14: 125 | C14: 0.84 | D14: 0.8 | E14: 2400 | F14: 0.12 | G14: 0.011
A15: Cybersecurity | B15: 95 | C15: 0.86 | D15: 0.82 | E15: 2600 | F15: 0.13 | G15: 0.012
A16: Application Development | B16: 180 | C16: 0.8 | D16: 0.76 | E16: 2100 | F16: 0.105 | G16: 0.009
A17: Managed Services | B17: 155 | C17: 0.78 | D17: 0.74 | E17: 1950 | F17: 0.1 | G17: 0.008
A18: TOTAL / AVG | B18: =SUM(B13:B17) -> 700
A20: Forecast Model Inputs | B20: Value
A21: Working Hours / Month | B21: 160
A22: Annual Attrition Rate | B22: 0.1
A23: Subcontractor Cost % Revenue | B23: 0.075
A24: Facilities Cost / HC (₹m) | B24: 0.006
A25: Travel + Marketing + Other Opex % Revenue | B25: 0.045
A27: Independent 2027 Budget Inputs | B27: Value
A28: Annual HC Growth | B28: 0.02
A29: Annual Attrition Rate | B29: 0.1
A30: Utilization Change | B30: -0.01
A31: Billing Rate Growth | B31: 0.03
A32: Salary Inflation | B32: 0.05
A33: Other Opex Growth | B33: 0.04
A34: Subcontractor Cost % Revenue | B34: 0.075
A35: Facilities Cost / HC (₹m) | B35: 0.006
A36: Other Opex % Revenue | B36: 0.045

Sheet Actuals
A1: Historical Actuals by Business Unit (₹m unless stated)
A3: Month | B3: Fiscal Year | C3: Quarter | D3: Business Unit | E3: Total HC | F3: Billable HC | G3: Utilization % | H3: Billing Rate (₹/hr) | I3: Revenue (₹m) | J3: Personnel Cost (₹m) | K3: Subcontractor Cost (₹m) | L3: Software Cost (₹m) | M3: Facilities Cost (₹m) | N3: Travel Cost (₹m) | O3: Marketing Cost (₹m) | P3: Other Opex (₹m) | Q3: Total Cost (₹m) | R3: Gross Profit (₹m) | S3: Gross Margin % | T3: EBITDA (₹m) | U3: EBITDA Margin %
A4: 45658 | B4: 2025 | C4: Q1 | D4: Cloud Services | E4: 120 | F4: 98 | G4: 0.75718132 | H4: 2050 | I4: 24.338836 | J4: 12.6 | K4: 1.5820244 | L4: 1.08 | M4: 0.66 | N4: 0.29206604 | O4: 0.19471069 | P4: 0.38942138 | Q4: 16.798222 | R4: 10.156812 | S4: 0.41730886 | T4: 7.540614 | U4: 0.30981818
A5: 45658 | B5: 2025 | C5: Q1 | D5: Data & Analytics | E5: 102 | F5: 85 | G5: 0.77441359 | H5: 2200 | I5: 23.170455 | J5: 11.22 | K5: 1.5987614 | L5: 1.02 | M5: 0.561 | N5: 0.27804545 | O5: 0.18536364 | P5: 0.37072727 | Q5: 15.233898 | R5: 10.351693 | S5: 0.44676263 | T5: 7.9365568 | U5: 0.34252918
A6: 45658 | B6: 2025 | C6: Q1 | D6: Cybersecurity | E6: 76 | F6: 65 | G6: 0.80241495 | H6: 2400 | I6: 20.028277 | J6: 9.12 | K6: 1.4620642 | L6: 0.836 | M6: 0.418 | N6: 0.24033933 | O6: 0.16022622 | P6: 0.32045244 | Q6: 12.557082 | R6: 9.446213 | S6: 0.47164381 | T6: 7.471195 | U6: 0.37303233
A7: 45658 | B7: 2025 | C7: Q1 | D7: Application Development | E7: 155 | F7: 122 | G7: 0.73315898 | H7: 1950 | I7: 27.906963 | J7: 14.88 | K7: 2.1488362 | L7: 1.24 | M7: 0.8525 | N7: 0.33488356 | O7: 0.22325571 | P7: 0.44651141 | Q7: 20.125987 | R7: 10.878127 | S7: 0.38979975 | T7: 7.7809766 | U7: 0.27881846
A8: 45658 | B8: 2025 | C8: Q1 | D8: Managed Services | E8: 132 | F8: 102 | G8: 0.72057411 | H8: 1800 | I8: 21.167585 | J8: 12.144 | K8: 1.7145744 | L8: 0.924 | M8: 0.726 | N8: 0.25401102 | O8: 0.16934068 | P8: 0.33868136 | Q8: 16.270607 | R8: 7.3090107 | S8: 0.34529261 | T8: 4.8969777 | U8: 0.23134324
A9: 45689 | B9: 2025 | C9: Q1 | D9: Cloud Services | E9: 121 | F9: 99 | G9: 0.75935102 | H9: 2054.1 | I9: 24.706962 | J9: 12.705 | K9: 1.6059525 | L9: 1.089 | M9: 0.6655 | N9: 0.37060443 | O9: 0.19765569 | P9: 0.39531139 | Q9: 17.029024 | R9: 10.396009 | S9: 0.42077247 | T9: 7.6779377 | U9: 0.31076009
A10: 45689 | B10: 2025 | C10: Q1 | D10: Data & Analytics | E10: 103 | F10: 85 | G10: 0.77442798 | H10: 2204.4 | I10: 23.217227 | J10: 11.33 | K10: 1.6019887 | L10: 1.03 | M10: 0.5665 | N10: 0.34825841 | O10: 0.18573782 | P10: 0.37147563 | Q10: 15.433961 | R10: 10.285238 | S10: 0.44300029 | T10: 7.7832665 | U10: 0.3352367
A11: 45689 | B11: 2025 | C11: Q1 | D11: Cybersecurity | E11: 77 | F11: 65 | G11: 0.80161897 | H11: 2404.8 | I11: 20.048426 | J11: 9.24 | K11: 1.4635351 | L11: 0.847 | M11: 0.4235 | N11: 0.3007264 | O11: 0.16038741 | P11: 0.32077482 | Q11: 12.755924 | R11: 9.3448912 | S11: 0.46611595 | T11: 7.2925026 | U11: 0.36374439
A12: 45689 | B12: 2025 | C12: Q1 | D12: Application Development | E12: 157 | F12: 124 | G12: 0.73409993 | H12: 1953.9 | I12: 28.45766 | J12: 15.072 | K12: 2.1912398 | L12: 1.256 | M12: 0.8635 | N12: 0.4268649 | O12: 0.22766128 | P12: 0.45532256 | Q12: 20.492589 | R12: 11.19442 | S12: 0.39337107 | T12: 7.9650713 | U12: 0.279892
A13: 45689 | B13: 2025 | C13: Q1 | D13: Managed Services | E13: 134 | F13: 103 | G13: 0.72043833 | H13: 1803.6 | I13: 21.413825 | J13: 12.328 | K13: 1.7345198 | L13: 0.938 | M13: 0.737 | N13: 0.32120737 | O13: 0.1713106 | P13: 0.3426212 | Q13: 16.572659 | R13: 7.351305 | S13: 0.34329715 | T13: 4.8411658 | U13: 0.22607665
A14: 45717 | B14: 2025 | C14: Q1 | D14: Cloud Services | E14: 122 | F14: 100 | G14: 0.75611769 | H14: 2058.2 | I14: 24.899863 | J14: 12.81 | K14: 1.6184911 | L14: 1.098 | M14: 0.671 | N14: 0.37349794 | O14: 0.1991989 | P14: 0.3983978 | Q14: 17.168586 | R14: 10.471372 | S14: 0.42053933 | T14: 7.731277 | U14: 0.31049477
A15: 45717 | B15: 2025 | C15: Q1 | D15: Data & Analytics | E15: 104 | F15: 86 | G15: 0.77645141 | H15: 2208.8 | I15: 23.598756 | J15: 11.44 | K15: 1.6283142 | L15: 1.04 | M15: 0.572 | N15: 0.35398134 | O15: 0.18879005 | P15: 0.3775801 | Q15: 15.600666 | R15: 10.530442 | S15: 0.44622868 | T15: 7.9980903 | U15: 0.33892
... A123: 46357 | B123: 2026 | C123: Q4 | D123: Managed Services | E123: 167 | F123: 129 | G123: 0.73426597 | H123: 1922.382 | I123: 29.134179 | J123: 16.28584 | K123: 2.3598685 | L123: 1.22745 | M123: 0.9185 | N123: 0.34961015 | O123: 0.23307343 | P123: 0.46614687 | Q123: 21.840489 | R123: 10.488471 | S123: 0.3600057 | T123: 7.2936901 | U123: 0.25034823

Sheet Revenue Forecast
A1: 2027 Driver-Based Revenue Forecast
A2: Case Selected: | B2: =Assumptions!B3 -> Base
A3: Month | B3: Business Unit | C3: Billable HC | D3: Base Utilization | E3: Scenario Utilization | F3: Working Hours | G3: Base Billing Rate (₹/hr) | H3: Scenario Billing Rate (₹/hr) | I3: Revenue Forecast (₹m) | J3: Revenue Driver
A4: 46388 | B4: Cloud Services | C4: ='Headcount Plan'!I4 -> 119.09817 | D4: =Assumptions!D13 -> 0.78 | E4: =MAX(0,MIN(0.95,D4+Assumptions!$B$6)) -> 0.78 | F4: =Assumptions!$B$21 -> 160 | G4: =Assumptions!E13 -> 2250 | H4: =G4*(1+Assumptions!$B$7) -> 2362.5 | I4: =C4*E4*F4*H4/1000000 -> 35.114903 | J4: Billable HC × utilization × hours × rate
A5: 46388 | B5: Data & Analytics | C5: ='Headcount Plan'!I5 -> 105.175 | D5: =Assumptions!D14 -> 0.8 | E5: =MAX(0,MIN(0.95,D5+Assumptions!$B$6)) -> 0.8 | F5: =Assumptions!$B$21 -> 160 | G5: =Assumptions!E14 -> 2400 | H5: =G5*(1+Assumptions!$B$7) -> 2520 | I5: =C5*E5*F5*H5/1000000 -> 33.925248 | J5: Billable HC × utilization × hours × rate
A6: 46388 | B6: Cybersecurity | C6: ='Headcount Plan'!I6 -> 81.836167 | D6: =Assumptions!D15 -> 0.82 | E6: =MAX(0,MIN(0.95,D6+Assumptions!$B$6)) -> 0.82 | F6: =Assumptions!$B$21 -> 160 | G6: =Assumptions!E15 -> 2600 | H6: =G6*(1+Assumptions!$B$7) -> 2730 | I6: =C6*E6*F6*H6/1000000 -> 29.311751 | J6: Billable HC × utilization × hours × rate
A7: 46388 | B7: Application Development | C7: ='Headcount Plan'!I7 -> 144.24 | D7: =Assumptions!D16 -> 0.76 | E7: =MAX(0,MIN(0.95,D7+Assumptions!$B$6)) -> 0.76 | F7: =Assumptions!$B$21 -> 160 | G7: =Assumptions!E16 -> 2100 | H7: =G7*(1+Assumptions!$B$7) -> 2205 | I7: =C7*E7*F7*H7/1000000 -> 38.674783 | J7: Billable HC × utilization × hours × rate
A8: 46388 | B8: Managed Services | C8: ='Headcount Plan'!I8 -> 121.1015 | D8: =Assumptions!D17 -> 0.74 | E8: =MAX(0,MIN(0.95,D8+Assumptions!$B$6)) -> 0.74 | F8: =Assumptions!$B$21 -> 160 | G8: =Assumptions!E17 -> 1950 | H8: =G8*(1+Assumptions!$B$7) -> 2047.5 | I8: =C8*E8*F8*H8/1000000 -> 29.35791 | J8: Billable HC × utilization × hours × rate
A9: 46419 | B9: Cloud Services | C9: ='Headcount Plan'!I9 -> 119.49516 | D9: =Assumptions!D13 -> 0.78 | E9: =MAX(0,MIN(0.95,D9+Assumptions!$B$6)) -> 0.78 | F9: =Assumptions!$B$21 -> 160 | G9: =Assumptions!E13 -> 2250 | H9: =G9*(1+Assumptions!$B$7) -> 2362.5 | I9: =C9*E9*F9*H9/1000000 -> 35.231953 | J9: Billable HC × utilization × hours × rate
A10: 46419 | B10: Data & Analytics | C10: ='Headcount Plan'!I10 -> 105.52558 | D10: =Assumptions!D14 -> 0.8 | E10: =MAX(0,MIN(0.95,D10+Assumptions!$B$6)) -> 0.8 | F10: =Assumptions!$B$21 -> 160 | G10: =Assumptions!E14 -> 2400 | H10: =G10*(1+Assumptions!$B$7) -> 2520 | I10: =C10*E10*F10*H10/1000000 -> 34.038332 | J10: Billable HC × utilization × hours × rate
A11: 46419 | B11: Cybersecurity | C11: ='Headcount Plan'!I11 -> 82.108954 | D11: =Assumptions!D15 -> 0.82 | E11: =MAX(0,MIN(0.95,D11+Assumptions!$B$6)) -> 0.82 | F11: =Assumptions!$B$21 -> 160 | G11: =Assumptions!E15 -> 2600 | H11: =G11*(1+Assumptions!$B$7) -> 2730 | I11: =C11*E11*F11*H11/1000000 -> 29.409457 | J11: Billable HC × utilization × hours × rate
A12: 46419 | B12: Application Development | C12: ='Headcount Plan'!I12 -> 144.7208 | D12: =Assumptions!D16 -> 0.76 | E12: =MAX(0,MIN(0.95,D12+Assumptions!$B$6)) -> 0.76 | F12: =Assumptions!$B$21 -> 160 | G12: =Assumptions!E16 -> 2100 | H12: =G12*(1+Assumptions!$B$7) -> 2205 | I12: =C12*E12*F12*H12/1000000 -> 38.803699 | J12: Billable HC × utilization × hours × rate
A13: 46419 | B13: Managed Services | C13: ='Headcount Plan'!I13 -> 121.50517 | D13: =Assumptions!D17 -> 0.74 | E13: =MAX(0,MIN(0.95,D13+Assumptions!$B$6)) -> 0.74 | F13: =Assumptions!$B$21 -> 160 | G13: =Assumptions!E17 -> 1950 | H13: =G13*(1+Assumptions!$B$7) -> 2047.5 | I13: =C13*E13*F13*H13/1000000 -> 29.45577 | J13: Billable HC × utilization × hours × rate
A14: 46447 | B14: Cloud Services | C14: ='Headcount Plan'!I14 -> 119.89348 | D14: =Assumptions!D13 -> 0.78 | E14: =MAX(0,MIN(0.95,D14+Assumptions!$B$6)) -> 0.78 | F14: =Assumptions!$B$21 -> 160 | G14: =Assumptions!E13 -> 2250 | H14: =G14*(1+Assumptions!$B$7) -> 2362.5 | I14: =C14*E14*F14*H14/1000000 -> 35.349393 | J14: Billable HC × utilization × hours × rate
A15: 46447 | B15: Data & Analytics | C15: ='Headcount Plan'!I15 -> 105.87734 | D15: =Assumptions!D14 -> 0.8 | E15: =MAX(0,MIN(0.95,D15+Assumptions!$B$6)) -> 0.8 | F15: =Assumptions!$B$21 -> 160 | G15: =Assumptions!E14 -> 2400 | H15: =G15*(1+Assumptions!$B$7) -> 2520 | I15: =C15*E15*F15*H15/1000000 -> 34.151793 | J15: Billable HC × utilization × hours × rate
A16: 46447 | B16: Cybersecurity | C16: ='Headcount Plan'!I16 -> 82.38265 | D16: =Assumptions!D15 -> 0.82 | E16: =MAX(0,MIN(0.95,D16+Assumptions!$B$6)) -> 0.82 | F16: =Assumptions!$B$21 -> 160 | G16: =Assumptions!E15 -> 2600 | H16: =G16*(1+Assumptions!$B$7) -> 2730 | I16: =C16*E16*F16*H16/1000000 -> 29.507488 | J16: Billable HC × utilization × hours × rate
A17: 46447 | B17: Application Development | C17: ='Headcount Plan'!I17 -> 145.2032 | D17: =Assumptions!D16 -> 0.76 | E17: =MAX(0,MIN(0.95,D17+Assumptions!$B$6)) -> 0.76 | F17: =Assumptions!$B$21 -> 160 | G17: =Assumptions!E16 -> 2100 | H17: =G17*(1+Assumptions!$B$7) -> 2205 | I17: =C17*E17*F17*H17/1000000 -> 38.933044 | J17: Billable HC × utilization × hours × rate
A18: 46447 | B18: Managed Services | C18: ='Headcount Plan'!I18 -> 121.91019 | D18: =Assumptions!D17 -> 0.74 | E18: =MAX(0,MIN(0.95,D18+Assumptions!$B$6)) -> 0.74 | F18: =Assumptions!$B$21 -> 160 | G18: =Assumptions!E17 -> 1950 | H18: =G18*(1+Assumptions!$B$7) -> 2047.5 | I18: =C18*E18*F18*H18/1000000 -> 29.553956 | J18: Billable HC × utilization × hours × rate
A19: 46478 | B19: Cloud Services | C19: ='Headcount Plan'!I19 -> 120.29312 | D19: =Assumptions!D13 -> 0.78 | E19: =MAX(0,MIN(0.95,D19+Assumptions!$B$6)) -> 0.78 | F19: =Assumptions!$B$21 -> 160 | G19: =Assumptions!E13 -> 2250 | H19: =G19*(1+Assumptions!$B$7) -> 2362.5 | I19: =C19*E19*F19*H19/1000000 -> 35.467224 | J19: Billable HC × utilization × hours × rate
A20: 46478 | B20: Data & Analytics | C20: ='Headcount Plan'!I20 -> 106.23026 | D20: =Assumptions!D14 -> 0.8 | E20: =MAX(0,MIN(0.95,D20+Assumptions!$B$6)) -> 0.8 | F20: =Assumptions!$B$21 -> 160 | G20: =Assumptions!E14 -> 2400 | H20: =G20*(1+Assumptions!$B$7) -> 2520 | I20: =C20*E20*F20*H20/1000000 -> 34.265633 | J20: Billable HC × utilization × hours × rate
A21: 46478 | B21: Cybersecurity | C21: ='Headcount Plan'!I21 -> 82.657259 | D21: =Assumptions!D15 -> 0.82 | E21: =MAX(0,MIN(0.95,D21+Assumptions!$B$6)) -> 0.82 | F21: =Assumptions!$B$21 -> 160 | G21: =Assumptions!E15 -> 2600 | H21: =G21*(1+Assumptions!$B$7) -> 2730 | I21: =C21*E21*F21*H21/1000000 -> 29.605846 | J21: Billable HC × utilization × hours × rate
A22: 46478 | B22: Application Development | C22: ='Headcount Plan'!I22 -> 145.68721 | D22: =Assumptions!D16 -> 0.76 | E22: =MAX(0,MIN(0.95,D22+Assumptions!$B$6)) -> 0.76 | F22: =Assumptions!$B$21 -> 160 | G22: =Assumptions!E16 -> 2100 | H22: =G22*(1+Assumptions!$B$7) -> 2205 | I22: =C22*E22*F22*H22/1000000 -> 39.062821 | J22: Billable HC × utilization × hours × rate
A23: 46478 | B23: Managed Services | C23: ='Headcount Plan'!I23 -> 122.31656 | D23: =Assumptions!D17 -> 0.74 | E23: =MAX(0,MIN(0.95,D23+Assumptions!$B$6)) -> 0.74 | F23: =Assumptions!$B$21 -> 160 | G23: =Assumptions!E17 -> 1950 | H23: =G23*(1+Assumptions!$B$7) -> 2047.5 | I23: =C23*E23*F23*H23/1000000 -> 29.652469 | J23: Billable HC × utilization × hours × rate
A24: 46508 | B24: Cloud Services | C24: ='Headcount Plan'!I24 -> 120.6941 | D24: =Assumptions!D13 -> 0.78 | E24: =MAX(0,MIN(0.95,D24+Assumptions!$B$6)) -> 0.78 | F24: =Assumptions!$B$21 -> 160 | G24: =Assumptions!E13 -> 2250 | H24: =G24*(1+Assumptions!$B$7) -> 2362.5 | I24: =C24*E24*F24*H24/1000000 -> 35.585448 | J24: Billable HC × utilization × hours × rate
A25: 46508 | B25: Data & Analytics | C25: ='Headcount Plan'!I25 -> 106.58436 | D25: =Assumptions!D14 -> 0.8 | E25: =MAX(0,MIN(0.95,D25+Assumptions!$B$6)) -> 0.8 | F25: =Assumptions!$B$21 -> 160 | G25: =Assumptions!E14 -> 2400 | H25: =G25*(1+Assumptions!$B$7) -> 2520 | I25: =C25*E25*F25*H25/1000000 -> 34.379851 | J25: Billable HC × utilization × hours × rate
A26: 46508 | B26: Cybersecurity | C26: ='Headcount Plan'!I26 -> 82.932783 | D26: =Assumptions!D15 -> 0.82 | E26: =MAX(0,MIN(0.95,D26+Assumptions!$B$6)) -> 0.82 | F26: =Assumptions!$B$21 -> 160 | G26: =Assumptions!E15 -> 2600 | H26: =G26*(1+Assumptions!$B$7) -> 2730 | I26: =C26*E26*F26*H26/1000000 -> 29.704533 | J26: Billable HC × utilization × hours × rate
A27: 46508 | B27: Application Development | C27: ='Headcount Plan'!I27 -> 146.17284 | D27: =Assumptions!D16 -> 0.76 | E27: =MAX(0,MIN(0.95,D27+Assumptions!$B$6)) -> 0.76 | F27: =Assumptions!$B$21 -> 160 | G27: =Assumptions!E16 -> 2100 | H27: =G27*(1+Assumptions!$B$7) -> 2205 | I27: =C27*E27*F27*H27/1000000 -> 39.193031 | J27: Billable HC × utilization × hours × rate
A28: 46508 | B28: Managed Services | C28: ='Headcount Plan'!I28 -> 122.72428 | D28: =Assumptions!D17 -> 0.74 | E28: =MAX(0,MIN(0.95,D28+Assumptions!$B$6)) -> 0.74 | F28: =Assumptions!$B$21 -> 160 | G28: =Assumptions!E17 -> 1950 | H28: =G28*(1+Assumptions!$B$7) -> 2047.5 | I28: =C28*E28*F28*H28/1000000 -> 29.75131 | J28: Billable HC × utilization × hours × rate
A29: 46539 | B29: Cloud Services | C29: ='Headcount Plan'!I29 -> 121.09641 | D29: =Assumptions!D13 -> 0.78 | E29: =MAX(0,MIN(0.95,D29+Assumptions!$B$6)) -> 0.78 | F29: =Assumptions!$B$21 -> 160 | G29: =Assumptions!E13 -> 2250 | H29: =G29*(1+Assumptions!$B$7) -> 2362.5 | I29: =C29*E29*F29*H29/1000000 -> 35.704067 | J29: Billable HC × utilization × hours × rate
A30: 46539 | B30: Data & Analytics | C30: ='Headcount Plan'!I30 -> 106.93964 | D30: =Assumptions!D14 -> 0.8 | E30: =MAX(0,MIN(0.95,D30+Assumptions!$B$6)) -> 0.8 | F30: =Assumptions!$B$21 -> 160 | G30: =Assumptions!E14 -> 2400 | H30: =G30*(1+Assumptions!$B$7) -> 2520 | I30: =C30*E30*F30*H30/1000000 -> 34.494451 | J30: Billable HC × utilization × hours × rate
A31: 46539 | B31: Cybersecurity | C31: ='Headcount Plan'!I31 -> 83.209226 | D31: =Assumptions!D15 -> 0.82 | E31: =MAX(0,MIN(0.95,D31+Assumptions!$B$6)) -> 0.82 | F31: =Assumptions!$B$21 -> 160 | G31: =Assumptions!E15 -> 2600 | H31: =G31*(1+Assumptions!$B$7) -> 2730 | I31: =C31*E31*F31*H31/1000000 -> 29.803548 | J31: Billable HC × utilization × hours × rate
A32: 46539 | B32: Application Development | C32: ='Headcount Plan'!I32 -> 146.66008 | D32: =Assumptions!D16 -> 0.76 | E32: =MAX(0,MIN(0.95,D32+Assumptions!$B$6)) -> 0.76 | F32: =Assumptions!$B$21 -> 160 | G32: =Assumptions!E16 -> 2100 | H32: =G32*(1+Assumptions!$B$7) -> 2205 | I32: =C32*E32*F32*H32/1000000 -> 39.323674 | J32: Billable HC × utilization × hours × rate
A33: 46539 | B33: Managed Services | C33: ='Headcount Plan'!I33 -> 123.13336 | D33: =Assumptions!D17 -> 0.74 | E33: =MAX(0,MIN(0.95,D33+Assumptions!$B$6)) -> 0.74 | F33: =Assumptions!$B$21 -> 160 | G33: =Assumptions!E17 -> 1950 | H33: =G33*(1+Assumptions!$B$7) -> 2047.5 | I33: =C33*E33*F33*H33/1000000 -> 29.850481 | J33: Billable HC × utilization × hours × rate
A34: 46569 | B34: Cloud Services | C34: ='Headcount Plan'!I34 -> 121.50007 | D34: =Assumptions!D13 -> 0.78 | E34: =MAX(0,MIN(0.95,D34+Assumptions!$B$6)) -> 0.78 | F34: =Assumptions!$B$21 -> 160 | G34: =Assumptions!E13 -> 2250 | H34: =G34*(1+Assumptions!$B$7) -> 2362.5 | I34: =C34*E34*F34*H34/1000000 -> 35.82308 | J34: Billable HC × utilization × hours × rate
A35: 46569 | B35: Data & Analytics | C35: ='Headcount Plan'!I35 -> 107.29611 | D35: =Assumptions!D14 -> 0.8 | E35: =MAX(0,MIN(0.95,D35+Assumptions!$B$6)) -> 0.8 | F35: =Assumptions!$B$21 -> 160 | G35: =Assumptions!E14 -> 2400 | H35: =G35*(1+Assumptions!$B$7) -> 2520 | I35: =C35*E35*F35*H35/1000000 -> 34.609432 | J35: Billable HC × utilization × hours × rate
A36: 46569 | B36: Cybersecurity | C36: ='Headcount Plan'!I36 -> 83.48659 | D36: =Assumptions!D15 -> 0.82 | E36: =MAX(0,MIN(0.95,D36+Assumptions!$B$6)) -> 0.82 | F36: =Assumptions!$B$21 -> 160 | G36: =Assumptions!E15 -> 2600 | H36: =G36*(1+Assumptions!$B$7) -> 2730 | I36: =C36*E36*F36*H36/1000000 -> 29.902893 | J36: Billable HC × utilization × hours × rate
A37: 46569 | B37: Application Development | C37: ='Headcount Plan'!I37 -> 147.14895 | D37: =Assumptions!D16 -> 0.76 | E37: =MAX(0,MIN(0.95,D37+Assumptions!$B$6)) -> 0.76 | F37: =Assumptions!$B$21 -> 160 | G37: =Assumptions!E16 -> 2100 | H37: =G37*(1+Assumptions!$B$7) -> 2205 | I37: =C37*E37*F37*H37/1000000 -> 39.454753 | J37: Billable HC × utilization × hours × rate
A38: 46569 | B38: Managed Services | C38: ='Headcount Plan'!I38 -> 123.5438 | D38: =Assumptions!D17 -> 0.74 | E38: =MAX(0,MIN(0.95,D38+Assumptions!$B$6)) -> 0.74 | F38: =Assumptions!$B$21 -> 160 | G38: =Assumptions!E17 -> 1950 | H38: =G38*(1+Assumptions!$B$7) -> 2047.5 | I38: =C38*E38*F38*H38/1000000 -> 29.949983 | J38: Billable HC × utilization × hours × rate
A39: 46600 | B39: Cloud Services | C39: ='Headcount Plan'!I39 -> 121.90507 | D39: =Assumptions!D13 -> 0.78 | E39: =MAX(0,MIN(0.95,D39+Assumptions!$B$6)) -> 0.78 | F39: =Assumptions!$B$21 -> 160 | G39: =Assumptions!E13 -> 2250 | H39: =G39*(1+Assumptions!$B$7) -> 2362.5 | I39: =C39*E39*F39*H39/1000000 -> 35.94249 | J39: Billable HC × utilization × hours × rate
A40: 46600 | B40: Data & Analytics | C40: ='Headcount Plan'!I40 -> 107.65376 | D40: =Assumptions!D14 -> 0.8 | E40: =MAX(0,MIN(0.95,D40+Assumptions!$B$6)) -> 0.8 | F40: =Assumptions!$B$21 -> 160 | G40: =Assumptions!E14 -> 2400 | H40: =G40*(1+Assumptions!$B$7) -> 2520 | I40: =C40*E40*F40*H40/1000000 -> 34.724797 | J40: Billable HC × utilization × hours × rate
...

Sheet Headcount Plan
A1: 2027 Headcount and Personnel Cost Forecast
A2: Case Selected: | B2: =Assumptions!B3 -> Base
A3: Month | B3: Business Unit | C3: Opening HC | D3: Gross Hires | E3: Attrition | F3: Closing HC | G3: Average HC | H3: Billable % | I3: Billable HC | J3: Avg Salary / Month (₹m) | K3: Personnel Cost (₹m)
A4: 46388 | B4: Cloud Services | C4: =Assumptions!B13 -> 145 | D4: =C4*(Assumptions!$B$22+Assumptions!$B$10)/12 -> 1.6916667 | E4: =C4*Assumptions!$B$22/12 -> 1.2083333 | F4: =C4+D4-E4 -> 145.48333 | G4: =(C4+F4)/2 -> 145.24167 | H4: =Assumptions!C13 -> 0.82 | I4: =G4*H4 -> 119.09817 | J4: =Assumptions!F13*(1+Assumptions!$B$8) -> 0.1219 | K4: =G4*J4 -> 17.704959
A5: 46388 | B5: Data & Analytics | C5: =Assumptions!B14 -> 125 | D5: =C5*(Assumptions!$B$22+Assumptions!$B$10)/12 -> 1.4583333 | E5: =C5*Assumptions!$B$22/12 -> 1.0416667 | F5: =C5+D5-E5 -> 125.41667 | G5: =(C5+F5)/2 -> 125.20833 | H5: =Assumptions!C14 -> 0.84 | I5: =G5*H5 -> 105.175 | J5: =Assumptions!F14*(1+Assumptions!$B$8) -> 0.1272 | K5: =G5*J5 -> 15.9265
A6: 46388 | B6: Cybersecurity | C6: =Assumptions!B15 -> 95 | D6: =C6*(Assumptions!$B$22+Assumptions!$B$10)/12 -> 1.1083333 | E6: =C6*Assumptions!$B$22/12 -> 0.79166667 | F6: =C6+D6-E6 -> 95.316667 | G6: =(C6+F6)/2 -> 95.158333 | H6: =Assumptions!C15 -> 0.86 | I6: =G6*H6 -> 81.836167 | J6: =Assumptions!F15*(1+Assumptions!$B$8) -> 0.1378 | K6: =G6*J6 -> 13.112818
A7: 46388 | B7: Application Development | C7: =Assumptions!B16 -> 180 | D7: =C7*(Assumptions!$B$22+Assumptions!$B$10)/12 -> 2.1 | E7: =C7*Assumptions!$B$22/12 -> 1.5 | F7: =C7+D7-E7 -> 180.6 | G7: =(C7+F7)/2 -> 180.3 | H7: =Assumptions!C16 -> 0.8 | I7: =G7*H7 -> 144.24 | J7: =Assumptions!F16*(1+Assumptions!$B$8) -> 0.1113 | K7: =G7*J7 -> 20.06739
A8: 46388 | B8: Managed Services | C8: =Assumptions!B17 -> 155 | D8: =C8*(Assumptions!$B$22+Assumptions!$B$10)/12 -> 1.8083333 | E8: =C8*Assumptions!$B$22/12 -> 1.2916667 | F8: =C8+D8-E8 -> 155.51667 | G8: =(C8+F8)/2 -> 155.25833 | H8: =Assumptions!C17 -> 0.78 | I8: =G8*H8 -> 121.1015 | J8: =Assumptions!F17*(1+Assumptions!$B$8) -> 0.106 | K8: =G8*J8 -> 16.457383
A9: 46419 | B9: Cloud Services | C9: =F4 -> 145.48333 | D9: =C9*(Assumptions!$B$22+Assumptions!$B$10)/12 -> 1.6973056 | E9: =C9*Assumptions!$B$22/12 -> 1.2123611 | F9: =C9+D9-E9 -> 145.96828 | G9: =(C9+F9)/2 -> 145.72581 | H9: =Assumptions!C13 -> 0.82 | I9: =G9*H9 -> 119.49516 | J9: =Assumptions!F13*(1+Assumptions!$B$8) -> 0.1219 | K9: =G9*J9 -> 17.763976
A10: 46419 | B10: Data & Analytics | C10: =F5 -> 125.41667 | D10: =C10*(Assumptions!$B$22+Assumptions!$B$10)/12 -> 1.4631944 | E10: =C10*Assumptions!$B$22/12 -> 1.0451389 | F10: =C10+D10-E10 -> 125.83472 | G10: =(C10+F10)/2 -> 125.62569 | H10: =Assumptions!C14 -> 0.84 | I10: =G10*H10 -> 105.52558 | J10: =Assumptions!F14*(1+Assumptions!$B$8) -> 0.1272 | K10: =G10*J10 -> 15.979588
A11: 46419 | B11: Cybersecurity | C11: =F6 -> 95.316667 | D11: =C11*(Assumptions!$B$22+Assumptions!$B$10)/12 -> 1.1120278 | E11: =C11*Assumptions!$B$22/12 -> 0.79430556 | F11: =C11+D11-E11 -> 95.634389 | G11: =(C11+F11)/2 -> 95.475528 | H11: =Assumptions!C15 -> 0.86 | I11: =G11*H11 -> 82.108954 | J11: =Assumptions!F15*(1+Assumptions!$B$8) -> 0.1378 | K11: =G11*J11 -> 13.156528
A12: 46419 | B12: Application Development | C12: =F7 -> 180.6 | D12: =C12*(Assumptions!$B$22+Assumptions!$B$10)/12 -> 2.107 | E12: =C12*Assumptions!$B$22/12 -> 1.505 | F12: =C12+D12-E12 -> 181.202 | G12: =(C12+F12)/2 -> 180.901 | H12: =Assumptions!C16 -> 0.8 | I12: =G12*H12 -> 144.7208 | J12: =Assumptions!F16*(1+Assumptions!$B$8) -> 0.1113 | K12: =G12*J12 -> 20.134281
A13: 46419 | B13: Managed Services | C13: =F8 -> 155.51667 | D13: =C13*(Assumptions!$B$22+Assumptions!$B$10)/12 -> 1.8143611 | E13: =C13*Assumptions!$B$22/12 -> 1.2959722 | F13: =C13+D13-E13 -> 156.03506 | G13: =(C13+F13)/2 -> 155.77586 | H13: =Assumptions!C17 -> 0.78 | I13: =G13*H13 -> 121.50517 | J13: =Assumptions!F17*(1+Assumptions!$B$8) -> 0.106 | K13: =G13*J13 -> 16.512241
A14: 46447 | B14: Cloud Services | C14: =F9 -> 145.96828 | D14: =C14*(Assumptions!$B$22+Assumptions!$B$10)/12 -> 1.7029632 | E14: =C14*Assumptions!$B$22/12 -> 1.2164023 | F14: =C14+D14-E14 -> 146.45484 | G14: =(C14+F14)/2 -> 146.21156 | H14: =Assumptions!C13 -> 0.82 | I14: =G14*H14 -> 119.89348 | J14: =Assumptions!F13*(1+Assumptions!$B$8) -> 0.1219 | K14: =G14*J14 -> 17.823189
A15: 46447 | B15: Data & Analytics | C15: =F10 -> 125.83472 | D15: =C15*(Assumptions!$B$22+Assumptions!$B$10)/12 -> 1.4680718 | E15: =C15*Assumptions!$B$22/12 -> 1.0486227 | F15: =C15+D15-E15 -> 126.25417 | G15: =(C15+F15)/2 -> 126.04445 | H15: =Assumptions!C14 -> 0.84 | I15: =G15*H15 -> 105.87734 | J15: =Assumptions!F14*(1+Assumptions!$B$8) -> 0.1272 | K15: =G15*J15 -> 16.032854
A16: 46447 | B16: Cybersecurity | C16: =F11 -> 95.634389 | D16: =C16*(Assumptions!$B$22+Assumptions!$B$10)/12 -> 1.1157345 | E16: =C16*Assumptions!$B$22/12 -> 0.79695324 | F16: =C16+D16-E16 -> 95.95317 | G16: =(C16+F16)/2 -> 95.79378 | H16: =Assumptions!C15 -> 0.86 | I16: =G16*H16 -> 82.38265 | J16: =Assumptions!F15*(1+Assumptions!$B$8) -> 0.1378 | K16: =G16*J16 -> 13.200383
A17: 46447 | B17: Application Development | C17: =F12 -> 181.202 | D17: =C17*(Assumptions!$B$22+Assumptions!$B$10)/12 -> 2.1140233 | E17: =C17*Assumptions!$B$22/12 -> 1.5100167 | F17: =C17+D17-E17 -> 181.80601 | G17: =(C17+F17)/2 -> 181.504 | H17: =Assumptions!C16 -> 0.8 | I17: =G17*H17 -> 145.2032 | J17: =Assumptions!F16*(1+Assumptions!$B$8) -> 0.1113 | K17: =G17*J17 -> 20.201396
A18: 46447 | B18: Managed Services | C18: =F13 -> 156.03506 | D18: =C18*(Assumptions!$B$22+Assumptions!$B$10)/12 -> 1.820409 | E18: =C18*Assumptions!$B$22/12 -> 1.3002921 | F18: =C18+D18-E18 -> 156.55517 | G18: =(C18+F18)/2 -> 156.29511 | H18: =Assumptions!C17 -> 0.78 | I18: =G18*H18 -> 121.91019 | J18: =Assumptions!F17*(1+Assumptions!$B$8) -> 0.106 | K18: =G18*J18 -> 16.567282
A19: 46478 | B19: Cloud Services | C19: =F14 -> 146.45484 | D19: =C19*(Assumptions!$B$22+Assumptions!$B$10)/12 -> 1.7086398 | E19: =C19*Assumptions!$B$22/12 -> 1.220457 | F19: =C19+D19-E19 -> 146.94302 | G19: =(C19+F19)/2 -> 146.69893 | H19: =Assumptions!C13 -> 0.82 | I19: =G19*H19 -> 120.29312 | J19: =Assumptions!F13*(1+Assumptions!$B$8) -> 0.1219 | K19: =G19*J19 -> 17.8826
A20: 46478 | B20: Data & Analytics | C20: =F15 -> 126.25417 | D20: =C20*(Assumptions!$B$22+Assumptions!$B$10)/12 -> 1.4729653 | E20: =C20*Assumptions!$B$22/12 -> 1.0521181 | F20: =C20+D20-E20 -> 126.67502 | G20: =(C20+F20)/2 -> 126.46459 | H20: =Assumptions!C14 -> 0.84 | I20: =G20*H20 -> 106.23026 | J20: =Assumptions!F14*(1+Assumptions!$B$8) -> 0.1272 | K20: =G20*J20 -> 16.086296
A21: 46478 | B21: Cybersecurity | C21: =F16 -> 95.95317 | D21: =C21*(Assumptions!$B$22+Assumptions!$B$10)/12 -> 1.1194537 | E21: =C21*Assumptions!$B$22/12 -> 0.79960975 | F21: =C21+D21-E21 -> 96.273014 | G21: =(C21+F21)/2 -> 96.113092 | H21: =Assumptions!C15 -> 0.86 | I21: =G21*H21 -> 82.657259 | J21: =Assumptions!F15*(1+Assumptions!$B$8) -> 0.1378 | K21: =G21*J21 -> 13.244384
A22: 46478 | B22: Application Development | C22: =F17 -> 181.80601 | D22: =C22*(Assumptions!$B$22+Assumptions!$B$10)/12 -> 2.1210701 | E22: =C22*Assumptions!$B$22/12 -> 1.5150501 | F22: =C22+D22-E22 -> 182.41203 | G22: =(C22+F22)/2 -> 182.10902 | H22: =Assumptions!C16 -> 0.8 | I22: =G22*H22 -> 145.68721 | J22: =Assumptions!F16*(1+Assumptions!$B$8) -> 0.1113 | K22: =G22*J22 -> 20.268734
A23: 46478 | B23: Managed Services | C23: =F18 -> 156.55517 | D23: =C23*(Assumptions!$B$22+Assumptions!$B$10)/12 -> 1.826477 | E23: =C23*Assumptions!$B$22/12 -> 1.3046264 | F23: =C23+D23-E23 -> 157.07702 | G23: =(C23+F23)/2 -> 156.8161 | H23: =Assumptions!C17 -> 0.78 | I23: =G23*H23 -> 122.31656 | J23: =Assumptions!F17*(1+Assumptions!$B$8) -> 0.106 | K23: =G23*J23 -> 16.622506
A24: 46508 | B24: Cloud Services | C24: =F19 -> 146.94302 | D24: =C24*(Assumptions!$B$22+Assumptions!$B$10)/12 -> 1.7143353 | E24: =C24*Assumptions!$B$22/12 -> 1.2245252 | F24: =C24+D24-E24 -> 147.43283 | G24: =(C24+F24)/2 -> 147.18793 | H24: =Assumptions!C13 -> 0.82 | I24: =G24*H24 -> 120.6941 | J24: =Assumptions!F13*(1+Assumptions!$B$8) -> 0.1219 | K24: =G24*J24 -> 17.942208
A25: 46508 | B25: Data & Analytics | C25: =F20 -> 126.67502 | D25: =C25*(Assumptions!$B$22+Assumptions!$B$10)/12 -> 1.4778752 | E25: =C25*Assumptions!$B$22/12 -> 1.0556252 | F25: =C25+D25-E25 -> 127.09727 | G25: =(C25+F25)/2 -> 126.88614 | H25: =Assumptions!C14 -> 0.84 | I25: =G25*H25 -> 106.58436 | J25: =Assumptions!F14*(1+Assumptions!$B$8) -> 0.1272 | K25: =G25*J25 -> 16.139917
A26: 46508 | B26: Cybersecurity | C26: =F21 -> 96.273014 | D26: =C26*(Assumptions!$B$22+Assumptions!$B$10)/12 -> 1.1231852 | E26: =C26*Assumptions!$B$22/12 -> 0.80227512 | F26: =C26+D26-E26 -> 96.593924 | G26: =(C26+F26)/2 -> 96.433469 | H26: =Assumptions!C15 -> 0.86 | I26: =G26*H26 -> 82.932783 | J26: =Assumptions!F15*(1+Assumptions!$B$8) -> 0.1378 | K26: =G26*J26 -> 13.288532
A27: 46508 | B27: Application Development | C27: =F22 -> 182.41203 | D27: =C27*(Assumptions!$B$22+Assumptions!$B$10)/12 -> 2.1281403 | E27: =C27*Assumptions!$B$22/12 -> 1.5201002 | F27: =C27+D27-E27 -> 183.02007 | G27: =(C27+F27)/2 -> 182.71605 | H27: =Assumptions!C16 -> 0.8 | I27: =G27*H27 -> 146.17284 | J27: =Assumptions!F16*(1+Assumptions!$B$8) -> 0.1113 | K27: =G27*J27 -> 20.336296
A28: 46508 | B28: Managed Services | C28: =F23 -> 157.07702 | D28: =C28*(Assumptions!$B$22+Assumptions!$B$10)/12 -> 1.8325653 | E28: =C28*Assumptions!$B$22/12 -> 1.3089752 | F28: =C28+D28-E28 -> 157.60061 | G28: =(C28+F28)/2 -> 157.33882 | H28: =Assumptions!C17 -> 0.78 | I28: =G28*H28 -> 122.72428 | J28: =Assumptions!F17*(1+Assumptions!$B$8) -> 0.106 | K28: =G28*J28 -> 16.677915
A29: 46539 | B29: Cloud Services | C29: =F24 -> 147.43283 | D29: =C29*(Assumptions!$B$22+Assumptions!$B$10)/12 -> 1.7200497 | E29: =C29*Assumptions!$B$22/12 -> 1.2286069 | F29: =C29+D29-E29 -> 147.92427 | G29: =(C29+F29)/2 -> 147.67855 | H29: =Assumptions!C13 -> 0.82 | I29: =G29*H29 -> 121.09641 | J29: =Assumptions!F13*(1+Assumptions!$B$8) -> 0.1219 | K29: =G29*J29 -> 18.002016
A30: 46539 | B30: Data & Analytics | C30: =F25 -> 127.09727 | D30: =C30*(Assumptions!$B$22+Assumptions!$B$10)/12 -> 1.4828015 | E30: =C30*Assumptions!$B$22/12 -> 1.0591439 | F30: =C30+D30-E30 -> 127.52093 | G30: =(C30+F30)/2 -> 127.3091 | H30: =Assumptions!C14 -> 0.84 | I30: =G30*H30 -> 106.93964 | J30: =Assumptions!F14*(1+Assumptions!$B$8) -> 0.1272 | K30: =G30*J30 -> 16.193717
A31: 46539 | B31: Cybersecurity | C31: =F26 -> 96.593924 | D31: =C31*(Assumptions!$B$22+Assumptions!$B$10)/12 -> 1.1269291 | E31: =C31*Assumptions!$B$22/12 -> 0.80494937 | F31: =C31+D31-E31 -> 96.915904 | G31: =(C31+F31)/2 -> 96.754914 | H31: =Assumptions!C15 -> 0.86 | I31: =G31*H31 -> 83.209226 | J31: =Assumptions!F15*(1+Assumptions!$B$8) -> 0.1378 | K31: =G31*J31 -> 13.332827
A32: 46539 | B32: Application Development | C32: =F27 -> 183.02007 | D32: =C32*(Assumptions!$B$22+Assumptions!$B$10)/12 -> 2.1352341 | E32: =C32*Assumptions!$B$22/12 -> 1.5251672 | F32: =C32+D32-E32 -> 183.63013 | G32: =(C32+F32)/2 -> 183.3251 | H32: =Assumptions!C16 -> 0.8 | I32: =G32*H32 -> 146.66008 | J32: =Assumptions!F16*(1+Assumptions!$B$8) -> 0.1113 | K32: =G32*J32 -> 20.404084
A33: 46539 | B33: Managed Services | C33: =F28 -> 157.60061 | D33: =C33*(Assumptions!$B$22+Assumptions!$B$10)/12 -> 1.8386738 | E33: =C33*Assumptions!$B$22/12 -> 1.3133384 | F33: =C33+D33-E33 -> 158.12595 | G33: =(C33+F33)/2 -> 157.86328 | H33: =Assumptions!C17 -> 0.78 | I33: =G33*H33 -> 123.13336 | J33: =Assumptions!F17*(1+Assumptions!$B$8) -> 0.106 | K33: =G33*J33 -> 16.733508
A34: 46569 | B34: Cloud Services | C34: =F29 -> 147.92427 | D34: =C34*(Assumptions!$B$22+Assumptions!$B$10)/12 -> 1.7257832 | E34: =C34*Assumptions!$B$22/12 -> 1.2327023 | F34: =C34+D34-E34 -> 148.41736 | G34: =(C34+F34)/2 -> 148.17081 | H34: =Assumptions!C13 -> 0.82 | I34: =G34*H34 -> 121.50007 | J34: =Assumptions!F13*(1+Assumptions!$B$8) -> 0.1219 | K34: =G34*J34 -> 18.062022
A35: 46569 | B35: Data & Analytics | C35: =F30 -> 127.52093 | D35: =C35*(Assumptions!$B$22+Assumptions!$B$10)/12 -> 1.4877441 | E35: =C35*Assumptions!$B$22/12 -> 1.0626744 | F35: =C35+D35-E35 -> 127.946 | G35: =(C35+F35)/2 -> 127.73346 | H35: =Assumptions!C14 -> 0.84 | I35: =G35*H35 -> 107.29611 | J35: =Assumptions!F14*(1+Assumptions!$B$8) -> 0.1272 | K35: =G35*J35 -> 16.247696
A36: 46569 | B36: Cybersecurity | C36: =F31 -> 96.915904 | D36: =C36*(Assumptions!$B$22+Assumptions!$B$10)/12 -> 1.1306855 | E36: =C36*Assumptions!$B$22/12 -> 0.80763253 | F36: =C36+D36-E36 -> 97.238957 | G36: =(C36+F36)/2 -> 97.07743 | H36: =Assumptions!C15 -> 0.86 | I36: =G36*H36 -> 83.48659 | J36: =Assumptions!F15*(1+Assumptions!$B$8) -> 0.1378 | K36: =G36*J36 -> 13.37727
A37: 46569 | B37: Application Development | C37: =F32 -> 183.63013 | D37: =C37*(Assumptions!$B$22+Assumptions!$B$10)/12 -> 2.1423516 | E37: =C37*Assumptions!$B$22/12 -> 1.5302511 | F37: =C37+D37-E37 -> 184.24223 | G37: =(C37+F37)/2 -> 183.93618 | H37: =Assumptions!C16 -> 0.8 | I37: =G37*H37 -> 147.14895 | J37: =Assumptions!F16*(1+Assumptions!$B$8) -> 0.1113 | K37: =G37*J37 -> 20.472097
A38: 46569 | B38: Managed Services | C38: =F33 -> 158.12595 | D38: =C38*(Assumptions!$B$22+Assumptions!$B$10)/12 -> 1.8448027 | E38: =C38*Assumptions!$B$22/12 -> 1.3177162 | F38: =C38+D38-E38 -> 158.65303 | G38: =(C38+F38)/2 -> 158.38949 | H38: =Assumptions!C17 -> 0.78 | I38: =G38*H38 -> 123.5438 | J38: =Assumptions!F17*(1+Assumptions!$B$8) -> 0.106 | K38: =G38*J38 -> 16.789286
A39: 46600 | B39: Cloud Services | C39: =F34 -> 148.41736 | D39: =C39*(Assumptions!$B$22+Assumptions!$B$10)/12 -> 1.7315358 | E39: =C39*Assumptions!$B$22/12 -> 1.2368113 | F39: =C39+D39-E39 -> 148.91208 | G39: =(C39+F39)/2 -> 148.66472 | H39: =Assumptions!C13 -> 0.82 | I39: =G39*H39 -> 121.90507 | J39: =Assumptions!F13*(1+Assumptions!$B$8) -> 0.1219 | K39: =G39*J39 -> 18.122229
A40: 46600 | B40: Data & Analytics | C40: =F35 -> 127.946 | D40: =C40*(Assumptions!$B$22+Assumptions!$B$10)/12 -> 1.4927033 | E40: =C40*Assumptions!$B$22/12 -> 1.0662166 | F40: =C40+D40-E40 -> 128.37248 | G40: =(C40+F40)/2 -> 128.15924 | H40: =Assumptions!C14 -> 0.84 | I40: =G40*H40 -> 107.65376 | J40: =Assumptions!F14*(1+Assumptions!$B$8) -> 0.1272 | K40: =G40*J40 -> 16.301855
...

Sheet Opex Forecast
A1: 2027 Operating Cost Forecast
A2: Case Selected: | B2: =Assumptions!B3 -> Base
A3: Month | B3: Average HC | C3: Revenue (₹m) | D3: Software (₹m) | E3: Facilities (₹m) | F3: Travel + Marketing + Other (₹m) | G3: Subcontractors (₹m) | H3: Personnel (₹m) | I3: Total Cost (₹m)
A4: 46388 | B4: =SUM('Headcount Plan'!G4:G8) -> 701.16667 | C4: =SUM('Revenue Forecast'!I4:I8) -> 166.3846 | D4: =SUMPRODUCT('Headcount Plan'!G4:G8,Assumptions!$G$13:$G$17)*(1+Assumptions!$B$9) -> 7.1781938 | E4: =B4*Assumptions!$B$24*(1+Assumptions!$B$9) -> 4.41735 | F4: =C4*Assumptions!$B$25*(1+Assumptions!$B$9) -> 7.8616721 | G4: =C4*Assumptions!$B$23 -> 12.478845 | H4: =SUM('Headcount Plan'!K4:K8) -> 83.269051 | I4: =SUM(D4:H4) -> 115.20511
A5: 46419 | B5: =SUM('Headcount Plan'!G9:G13) -> 703.50389 | C5: =SUM('Revenue Forecast'!I9:I13) -> 166.93921 | D5: =SUMPRODUCT('Headcount Plan'!G9:G13,Assumptions!$G$13:$G$17)*(1+Assumptions!$B$9) -> 7.2021211 | E5: =B5*Assumptions!$B$24*(1+Assumptions!$B$9) -> 4.4320745 | F5: =C5*Assumptions!$B$25*(1+Assumptions!$B$9) -> 7.8878777 | G5: =C5*Assumptions!$B$23 -> 12.520441 | H5: =SUM('Headcount Plan'!K9:K13) -> 83.546614 | I5: =SUM(D5:H5) -> 115.58913
A6: 46447 | B6: =SUM('Headcount Plan'!G14:G18) -> 705.8489 | C6: =SUM('Revenue Forecast'!I14:I18) -> 167.49567 | D6: =SUMPRODUCT('Headcount Plan'!G14:G18,Assumptions!$G$13:$G$17)*(1+Assumptions!$B$9) -> 7.2261281 | E6: =B6*Assumptions!$B$24*(1+Assumptions!$B$9) -> 4.4468481 | F6: =C6*Assumptions!$B$25*(1+Assumptions!$B$9) -> 7.9141706 | G6: =C6*Assumptions!$B$23 -> 12.562176 | H6: =SUM('Headcount Plan'!K14:K18) -> 83.825103 | I6: =SUM(D6:H6) -> 115.97443
A7: 46478 | B7: =SUM('Headcount Plan'!G19:G23) -> 708.20173 | C7: =SUM('Revenue Forecast'!I19:I23) -> 168.05399 | D7: =SUMPRODUCT('Headcount Plan'!G19:G23,Assumptions!$G$13:$G$17)*(1+Assumptions!$B$9) -> 7.2502152 | E7: =B7*Assumptions!$B$24*(1+Assumptions!$B$9) -> 4.4616709 | F7: =C7*Assumptions!$B$25*(1+Assumptions!$B$9) -> 7.9405512 | G7: =C7*Assumptions!$B$23 -> 12.604049 | H7: =SUM('Headcount Plan'!K19:K23) -> 84.10452 | I7: =SUM(D7:H7) -> 116.36101
A8: 46508 | B8: =SUM('Headcount Plan'!G24:G28) -> 710.5624 | C8: =SUM('Revenue Forecast'!I24:I28) -> 168.61417 | D8: =SUMPRODUCT('Headcount Plan'!G24:G28,Assumptions!$G$13:$G$17)*(1+Assumptions!$B$9) -> 7.2743826 | E8: =B8*Assumptions!$B$24*(1+Assumptions!$B$9) -> 4.4765431 | F8: =C8*Assumptions!$B$25*(1+Assumptions!$B$9) -> 7.9670197 | G8: =C8*Assumptions!$B$23 -> 12.646063 | H8: =SUM('Headcount Plan'!K24:K28) -> 84.384868 | I8: =SUM(D8:H8) -> 116.74888
A9: 46539 | B9: =SUM('Headcount Plan'!G29:G33) -> 712.93095 | C9: =SUM('Revenue Forecast'!I29:I33) -> 169.17622 | D9: =SUMPRODUCT('Headcount Plan'!G29:G33,Assumptions!$G$13:$G$17)*(1+Assumptions!$B$9) -> 7.2986306 | E9: =B9*Assumptions!$B$24*(1+Assumptions!$B$9) -> 4.491465 | F9: =C9*Assumptions!$B$25*(1+Assumptions!$B$9) -> 7.9935764 | G9: =C9*Assumptions!$B$23 -> 12.688217 | H9: =SUM('Headcount Plan'!K29:K33) -> 84.666151 | I9: =SUM(D9:H9) -> 117.13804
A10: 46569 | B10: =SUM('Headcount Plan'!G34:G38) -> 715.30738 | C10: =SUM('Revenue Forecast'!I34:I38) -> 169.74014 | D10: =SUMPRODUCT('Headcount Plan'!G34:G38,Assumptions!$G$13:$G$17)*(1+Assumptions!$B$9) -> 7.3229593 | E10: =B10*Assumptions!$B$24*(1+Assumptions!$B$9) -> 4.5064365 | F10: =C10*Assumptions!$B$25*(1+Assumptions!$B$9) -> 8.0202217 | G10: =C10*Assumptions!$B$23 -> 12.730511 | H10: =SUM('Headcount Plan'!K34:K38) -> 84.948372 | I10: =SUM(D10:H10) -> 117.5285
A11: 46600 | B11: =SUM('Headcount Plan'!G39:G43) -> 717.69174 | C11: =SUM('Revenue Forecast'!I39:I43) -> 170.30594 | D11: =SUMPRODUCT('Headcount Plan'!G39:G43,Assumptions!$G$13:$G$17)*(1+Assumptions!$B$9) -> 7.3473692 | E11: =B11*Assumptions!$B$24*(1+Assumptions!$B$9) -> 4.521458 | F11: =C11*Assumptions!$B$25*(1+Assumptions!$B$9) -> 8.0469557 | G11: =C11*Assumptions!$B$23 -> 12.772946 | H11: =SUM('Headcount Plan'!K39:K43) -> 85.231533 | I11: =SUM(D11:H11) -> 117.92026
A12: 46631 | B12: =SUM('Headcount Plan'!G44:G48) -> 720.08405 | C12: =SUM('Revenue Forecast'!I44:I48) -> 170.87363 | D12: =SUMPRODUCT('Headcount Plan'!G44:G48,Assumptions!$G$13:$G$17)*(1+Assumptions!$B$9) -> 7.3718604 | E12: =B12*Assumptions!$B$24*(1+Assumptions!$B$9) -> 4.5365295 | F12: =C12*Assumptions!$B$25*(1+Assumptions!$B$9) -> 8.0737789 | G12: =C12*Assumptions!$B$23 -> 12.815522 | H12: =SUM('Headcount Plan'!K44:K48) -> 85.515638 | I12: =SUM(D12:H12) -> 118.31333
A13: 46661 | B13: =SUM('Headcount Plan'!G49:G53) -> 722.48433 | C13: =SUM('Revenue Forecast'!I49:I53) -> 171.44321 | D13: =SUMPRODUCT('Headcount Plan'!G49:G53,Assumptions!$G$13:$G$17)*(1+Assumptions!$B$9) -> 7.3964333 | E13: =B13*Assumptions!$B$24*(1+Assumptions!$B$9) -> 4.5516513 | F13: =C13*Assumptions!$B$25*(1+Assumptions!$B$9) -> 8.1006915 | G13: =C13*Assumptions!$B$23 -> 12.858241 | H13: =SUM('Headcount Plan'!K49:K53) -> 85.80069 | I13: =SUM(D13:H13) -> 118.70771
A14: 46692 | B14: =SUM('Headcount Plan'!G54:G58) -> 724.89261 | C14: =SUM('Revenue Forecast'!I54:I58) -> 172.01468 | D14: =SUMPRODUCT('Headcount Plan'!G54:G58,Assumptions!$G$13:$G$17)*(1+Assumptions!$B$9) -> 7.4210881 | E14: =B14*Assumptions!$B$24*(1+Assumptions!$B$9) -> 4.5668234 | F14: =C14*Assumptions!$B$25*(1+Assumptions!$B$9) -> 8.1276938 | G14: =C14*Assumptions!$B$23 -> 12.901101 | H14: =SUM('Headcount Plan'!K54:K58) -> 86.086693 | I14: =SUM(D14:H14) -> 119.1034
A15: 46722 | B15: =SUM('Headcount Plan'!G59:G63) -> 727.30892 | C15: =SUM('Revenue Forecast'!I59:I63) -> 172.58807 | D15: =SUMPRODUCT('Headcount Plan'!G59:G63,Assumptions!$G$13:$G$17)*(1+Assumptions!$B$9) -> 7.445825 | E15: =B15*Assumptions!$B$24*(1+Assumptions!$B$9) -> 4.5820462 | F15: =C15*Assumptions!$B$25*(1+Assumptions!$B$9) -> 8.1547861 | G15: =C15*Assumptions!$B$23 -> 12.944105 | H15: =SUM('Headcount Plan'!K59:K63) -> 86.373648 | I15: =SUM(D15:H15) -> 119.50041

Sheet P&L
A1: Integrated Monthly P&L (₹m)
A2: Case Selected: | B2: =Assumptions!B3 -> Base
A3: Line Item | B3: 45658 | C3: 45689 | D3: 45717 | E3: 45748 | F3: 45778 | G3: 45809 | H3: 45839 | I3: 45870 | J3: 45901 | K3: 45931 | L3: 45962 | M3: 45992 | N3: 46023 | O3: 46054 | P3: 46082 | Q3: 46113 | R3: 46143 | S3: 46174 | T3: 46204 | U3: 46235 | V3: 46266 | W3: 46296 | X3: 46327 | Y3: 46357 | Z3: 46388 | AA3: 46419 | AB3: 46447 | AC3: 46478 | AD3: 46508 | AE3: 46539 | AF3: 46569 | AG3: 46600 | AH3: 46631 | AI3: 46661 | AJ3: 46692 | AK3: 46722 | AL3: 2025 Actual | AM3: 2026 Actual | AN3: 2027 Forecast
A4: Revenue | B4: =SUMIFS(Actuals!$I$4:$I$123,Actuals!$A$4:$A$123,B$3) -> 116.61212 | C4: =SUMIFS(Actuals!$I$4:$I$123,Actuals!$A$4:$A$123,C$3) -> 117.8441 | D4: =SUMIFS(Actuals!$I$4:$I$123,Actuals!$A$4:$A$123,D$3) -> 119.75911 | E4: =SUMIFS(Actuals!$I$4:$I$123,Actuals!$A$4:$A$123,E$3) -> 117.74867 | F4: =SUMIFS(Actuals!$I$4:$I$123,Actuals!$A$4:$A$123,F$3) -> 122.75101 | G4: =SUMIFS(Actuals!$I$4:$I$123,Actuals!$A$4:$A$123,G$3) -> 124.77301 | H4: =SUMIFS(Actuals!$I$4:$I$123,Actuals!$A$4:$A$123,H$3) -> 126.16668 | I4: =SUMIFS(Actuals!$I$4:$I$123,Actuals!$A$4:$A$123,I$3) -> 128.27071 | ... Y4: =SUMIFS(Actuals!$I$4:$I$123,Actuals!$A$4:$A$123,Y$3) -> 154.59837 | Z4: ='Opex Forecast'!C4 -> 166.3846 | AA4: ='Opex Forecast'!C5 -> 166.93921 | AB4: ='Opex Forecast'!C6 -> 167.49567 | AC4: ='Opex Forecast'!C7 -> 168.05399 | AD4: ='Opex Forecast'!C8 -> 168.61417 | AE4: ='Opex Forecast'!C9 -> 169.17622 | AF4: ='Opex Forecast'!C10 -> 169.74014 | AG4: ='Opex Forecast'!C11 -> 170.30594 | AH4: ='Opex Forecast'!C12 -> 170.87363 | AI4: ='Opex Forecast'!C13 -> 171.44321 | AJ4: ='Opex Forecast'!C14 -> 172.01468 | AK4: ='Opex Forecast'!C15 -> 172.58807 | AL4: =SUM(B4:M4) -> 1504.4942 | AM4: =SUM(N4:Y4) -> 1785.9819 | AN4: =SUM(Z4:AK4) -> 2033.6295
A5: Personnel Cost | B5: =SUMIFS(Actuals!$J$4:$J$123,Actuals!$A$4:$A$123,B$3) -> 59.964 | C5: =SUMIFS(Actuals!$J$4:$J$123,Actuals!$A$4:$A$123,C$3) -> 60.675 | D5: =SUMIFS(Actuals!$J$4:$J$123,Actuals!$A$4:$A$123,D$3) -> 61.198 | E5: =SUMIFS(Actuals!$J$4:$J$123,Actuals!$A$4:$A$123,E$3) -> 61.789 | F5: =SUMIFS(Actuals!$J$4:$J$123,Actuals!$A$4:$A$123,F$3) -> 62.097 | G5: =SUMIFS(Actuals!$J$4:$J$123,Actuals!$A$4:$A$123,G$3) -> 62.808 | H5: =SUMIFS(Actuals!$J$4:$J$123,Actuals!$A$4:$A$123,H$3) -> 63.331 | I5: =SUMIFS(Actuals!$J$4:$J$123,Actuals!$A$4:$A$123,I$3) -> 64.042 | ... Y5: =SUMIFS(Actuals!$J$4:$J$123,Actuals!$A$4:$A$123,Y$3) -> 77.40014 | Z5: ='Opex Forecast'!H4 -> 83.269051 | AA5: ='Opex Forecast'!H5 -> 83.546614 | AB5: ='Opex Forecast'!H6 -> 83.825103 | AC5: ='Opex Forecast'!H7 -> 84.10452 | AD5: ='Opex Forecast'!H8 -> 84.384868 | AE5: ='Opex Forecast'!H9 -> 84.666151 | AF5: ='Opex Forecast'!H10 -> 84.948372 | AG5: ='Opex Forecast'!H11 -> 85.231533 | AH5: ='Opex Forecast'!H12 -> 85.515638 | AI5: ='Opex Forecast'!H13 -> 85.80069 | AJ5: ='Opex Forecast'!H14 -> 86.086693 | AK5: ='Opex Forecast'!H15 -> 86.373648 | AL5: =SUM(B5:M5) -> 757.484 | AM5: =SUM(N5:Y5) -> 889.44388 | AN5: =SUM(Z5:AK5) -> 1017.7529
A6: Subcontractor Cost | B6: =SUMIFS(Actuals!$K$4:$K$123,Actuals!$A$4:$A$123,B$3) -> 8.5062605 | C6: =SUMIFS(Actuals!$K$4:$K$123,Actuals!$A$4:$A$123,C$3) -> 8.5972359 | D6: =SUMIFS(Actuals!$K$4:$K$123,Actuals!$A$4:$A$123,D$3) -> 8.7384995 | E6: =SUMIFS(Actuals!$K$4:$K$123,Actuals!$A$4:$A$123,E$3) -> 8.5896774 | F6: =SUMIFS(Actuals!$K$4:$K$123,Actuals!$A$4:$A$123,F$3) -> 8.9539695 | G6: =SUMIFS(Actuals!$K$4:$K$123,Actuals!$A$4:$A$123,G$3) -> 9.1083197 | H6: =SUMIFS(Actuals!$K$4:$K$123,Actuals!$A$4:$A$123,H$3) -> 9.2067876 | I6: =SUMIFS(Actuals!$K$4:$K$123,Actuals!$A$4:$A$123,I$3) -> 9.3639501 | ... Y6: =SUMIFS(Actuals!$K$4:$K$123,Actuals!$A$4:$A$123,Y$3) -> 11.305365 | Z6: ='Opex Forecast'!G4 -> 12.478845 | AA6: ='Opex Forecast'!G5 -> 12.520441 | AB6: ='Opex Forecast'!G6 -> 12.562176 | AC6: ='Opex Forecast'!G7 -> 12.604049 | AD6: ='Opex Forecast'!G8 -> 12.646063 | AE6: ='Opex Forecast'!G9 -> 12.688217 | AF6: ='Opex Forecast'!G10 -> 12.730511 | AG6: ='Opex Forecast'!G11 -> 12.772946 | AH6: ='Opex Forecast'!G12 -> 12.815522 | AI6: ='Opex Forecast'!G13 -> 12.858241 | AJ6: ='Opex Forecast'!G14 -> 12.901101 | AK6: ='Opex Forecast'!G15 -> 12.944105 | AL6: =SUM(B6:M6) -> 109.80065 | AM6: =SUM(N6:Y6) -> 130.50687 | AN6: =SUM(Z6:AK6) -> 152.52222
A7: Gross Profit | B7: =B4-B5-B6 -> 48.141856 | C7: =C4-C5-C6 -> 48.571864 | D7: =D4-D5-D6 -> 49.822615 | E7: =E4-E5-E6 -> 47.369995 | F7: =F4-F5-F6 -> 51.700043 | G7: =G4-G5-G6 -> 52.856685 | H7: =H4-H5-H6 -> 53.628895 | I7: =I4-I5-I6 -> 54.864762 | ... AN7: =AN4-AN5-AN6 -> 863.35444
A8: Gross Margin % | B8: =IFERROR(B7/B4,0) -> 0.41283751 | C8: =IFERROR(C7/C4,0) -> 0.41217052 | D8: =IFERROR(D7/D4,0) -> 0.41602358 | E8: =IFERROR(E7/E4,0) -> 0.40229749 | F8: =IFERROR(F7/F4,0) -> 0.42117814 | G8: =IFERROR(G7/G4,0) -> 0.42362276 | H8: =IFERROR(H7/H4,0) -> 0.42506385 | I8: =IFERROR(I7/I4,0) -> 0.42772634 | ... AM8: =IFERROR(AM7/AM4,0) -> 0.42891316 | AN8: =AN7/AN4 -> 0.4245387
A9: Software Cost | B9: =SUMIFS(Actuals!$L$4:$L$123,Actuals!$A$4:$A$123,B$3) -> 5.1 | C9: =SUMIFS(Actuals!$L$4:$L$123,Actuals!$A$4:$A$123,C$3) -> 5.16 | D9: =SUMIFS(Actuals!$L$4:$L$123,Actuals!$A$4:$A$123,D$3) -> 5.205 | E9: =SUMIFS(Actuals!$L$4:$L$123,Actuals!$A$4:$A$123,E$3) -> 5.254 | F9: =SUMIFS(Actuals!$L$4:$L$123,Actuals!$A$4:$A$123,F$3) -> 5.28 | G9: =SUMIFS(Actuals!$L$4:$L$123,Actuals!$A$4:$A$123,G$3) -> 5.34 | H9: =SUMIFS(Actuals!$L$4:$L$123,Actuals!$A$4:$A$123,H$3) -> 5.385 | I9: =SUMIFS(Actuals!$L$4:$L$123,Actuals!$A$4:$A$123,I$3) -> 5.445 | ... Y9: =SUMIFS(Actuals!$L$4:$L$123,Actuals!$A$4:$A$123,Y$3) -> 6.51525 | Z9: ='Opex Forecast'!D4 -> 7.1781938 | AA9: ='Opex Forecast'!D5 -> 7.2021211 | AB9: ='Opex Forecast'!D6 -> 7.2261281 | AC9: ='Opex Forecast'!D7 -> 7.2502152 | AD9: ='Opex Forecast'!D8 -> 7.2743826 | AE9: ='Opex Forecast'!D9 -> 7.2986306 | AF9: ='Opex Forecast'!D10 -> 7.3229593 | AG9: ='Opex Forecast'!D11 -> 7.3473692 | AH9: ='Opex Forecast'!D12 -> 7.3718604 | AI9: ='Opex Forecast'!D13 -> 7.3964333 | AJ9: ='Opex Forecast'!D14 -> 7.4210881 | AK9: ='Opex Forecast'!D15 -> 7.445825 | AL9: =SUM(B9:M9) -> 64.408 | AM9: =SUM(N9:Y9) -> 74.88285 | AN9: =SUM(Z9:AK9) -> 87.735207
A10: Facilities Cost | B10: =SUMIFS(Actuals!$M$4:$M$123,Actuals!$A$4:$A$123,B$3) -> 3.2175 | C10: =SUMIFS(Actuals!$M$4:$M$123,Actuals!$A$4:$A$123,C$3) -> 3.256 | D10: =SUMIFS(Actuals!$M$4:$M$123,Actuals!$A$4:$A$123,D$3) -> 3.2835 | E10: =SUMIFS(Actuals!$M$4:$M$123,Actuals!$A$4:$A$123,E$3) -> 3.3165 | F10: =SUMIFS(Actuals!$M$4:$M$123,Actuals!$A$4:$A$123,F$3) -> 3.333 | G10: =SUMIFS(Actuals!$M$4:$M$123,Actuals!$A$4:$A$123,G$3) -> 3.3715 | H10: =SUMIFS(Actuals!$M$4:$M$123,Actuals!$A$4:$A$123,H$3) -> 3.399 | I10: =SUMIFS(Actuals!$M$4:$M$123,Actuals!$A$4:$A$123,I$3) -> 3.4375 | ... Y10: =SUMIFS(Actuals!$M$4:$M$123,Actuals!$A$4:$A$123,Y$3) -> 3.9215 | Z10: ='Opex Forecast'!E4 -> 4.41735 | AA10: ='Opex Forecast'!E5 -> 4.4320745 | AB10: ='Opex Forecast'!E6 -> 4.4468481 | AC10: ='Opex Forecast'!E7 -> 4.4616709 | AD10: ='Opex Forecast'!E8 -> 4.4765431 | AE10: ='Opex Forecast'!E9 -> 4.491465 | AF10: ='Opex Forecast'!E10 -> 4.5064365 | AG10: ='Opex Forecast'!E11 -> 4.521458 | AH10: ='Opex Forecast'!E12 -> 4.5365295 | AI10: ='Opex Forecast'!E13 -> 4.5516513 | AJ10: ='Opex Forecast'!E14 -> 4.5668234 | AK10: ='Opex Forecast'!E15 -> 4.5820462 | AL10: =SUM(B10:M10) -> 40.656 | AM10: =SUM(N10:Y10) -> 45.056 | AN10: =SUM(Z10:AK10) -> 53.990896
A11: Travel + Marketing + Other Opex | B11: =SUMIFS(Actuals!$N$4:$N$123,Actuals!$A$4:$A$123,B$3)+SUMIFS(Actuals!$O$4:$O$123,Actuals!$A$4:$A$123,B$3)+SUMIFS(Actuals!$P$4:$P$123,Actuals!$A$4:$A$123,B$3) -> 4.1980362 | C11: =SUMIFS(Actuals!$N$4:$N$123,Actuals!$A$4:$A$123,C$3)+SUMIFS(Actuals!$O$4:$O$123,Actuals!$A$4:$A$123,C$3)+SUMIFS(Actuals!$P$4:$P$123,Actuals!$A$4:$A$123,C$3) -> 4.5959199 | D11: =SUMIFS(Actuals!$N$4:$N$123,Actuals!$A$4:$A$123,D$3)+SUMIFS(Actuals!$O$4:$O$123,Actuals!$A$4:$A$123,D$3)+SUMIFS(Actuals!$P$4:$P$123,Actuals!$A$4:$A$123,D$3) -> 4.6706055 | E11: =SUMIFS(Actuals!$N$4:$N$123,Actuals!$A$4:$A$123,E$3)+SUMIFS(Actuals!$O$4:$O$123,Actuals!$A$4:$A$123,E$3)+SUMIFS(Actuals!$P$4:$P$123,Actuals!$A$4:$A$123,E$3) -> 4.2389522 | F11: =SUMIFS(Actuals!$N$4:$N$123,Actuals!$A$4:$A$123,F$3)+SUMIFS(Actuals!$O$4:$O$123,Actuals!$A$4:$A$123,F$3)+SUMIFS(Actuals!$P$4:$P$123,Actuals!$A$4:$A$123,F$3) -> 4.4190365 | G11: =SUMIFS(Actuals!$N$4:$N$123,Actuals!$A$4:$A$123,G$3)+SUMIFS(Actuals!$O$4:$O$123,Actuals!$A$4:$A$123,G$3)+SUMIFS(Actuals!$P$4:$P$123,Actuals!$A$4:$A$123,G$3) -> 4.4918282 | H11: =SUMIFS(Actuals!$N$4:$N$123,Actuals!$A$4:$A$123,H$3)+SUMIFS(Actuals!$O$4:$O$123,Actuals!$A$4:$A$123,H$3)+SUMIFS(Actuals!$P$4:$P$123,Actuals!$A$4:$A$123,H$3) -> 4.5420006 | I11: =SUMIFS(Actuals!$N$4:$N$123,Actuals!$A$4:$A$123,I$3)+SUMIFS(Actuals!$O$4:$O$123,Actuals!$A$4:$A$123,I$3)+SUMIFS(Actuals!$P$4:$P$123,Actuals!$A$4:$A$123,I$3) -> 4.6177457 | ... Y11: =SUMIFS(Actuals!$N$4:$N$123,Actuals!$A$4:$A$123,Y$3)+SUMIFS(Actuals!$O$4:$O$123,Actuals!$A$4:$A$123,Y$3)+SUMIFS(Actuals!$P$4:$P$123,Actuals!$A$4:$A$123,Y$3) -> 5.5655414 | Z11: ='Opex Forecast'!F4 -> 7.8616721 | AA11: ='Opex Forecast'!F5 -> 7.8878777 | AB11: ='Opex Forecast'!F6 -> 7.9141706 | AC11: ='Opex Forecast'!F7 -> 7.9405512 | AD11: ='Opex Forecast'!F8 -> 7.9670197 | AE11: ='Opex Forecast'!F9 -> 7.9935764 | AF11: ='Opex Forecast'!F10 -> 8.0202217 | AG11: ='Opex Forecast'!F11 -> 8.0469557 | AH11: ='Opex Forecast'!F12 -> 8.0737789 | AI11: ='Opex Forecast'!F13 -> 8.1006915 | AJ11: ='Opex Forecast'!F14 -> 8.1276938 | AK11: ='Opex Forecast'!F15 -> 8.1547861 | AL11: =SUM(B11:M11) -> 55.675818 | AM11: =SUM(N11:Y11) -> 66.09189 | AN11: =SUM(Z11:AK11) -> 96.088996
A12: EBITDA | B12: =SUMIFS(Actuals!$T$4:$T$123,Actuals!$A$4:$A$123,B$3) -> 35.62632 | C12: 35.559944 | D12: 36.66351 | E12: 34.560543 | F12: 38.668007 | G12: 39.653357 | H12: 40.302895 | I12: 41.364517 | J12: 44.153686 | K12: 45.292438 | L12: 43.626823 | M12: 40.997745 | N12: 44.270067 | O12: 44.565589 | P12: 45.655222 | Q12: 41.788095 | R12: 46.6388 | S12: 47.787236 | T12: 49.658454 | U12: 50.198411 | V12: 52.759221 | W12: 53.579609 | X12: 53.209119 | Y12: 49.890575 | Z12: 51.179484 | AA12: 51.350082 | AB12: 51.521249 | AC12: 51.692986 | AD12: 51.865296 | AE12: 52.038181 | AF12: 52.211641 | AG12: 52.38568 | AH12: 52.560299 | AI12: 52.7355 | AJ12: 52.911285 | AK12: 53.087656 | AL12: 476.46978 | AM12: 580.0004 | AN12: =AN7-AN9-AN10-AN11 -> 625.53934
A13: EBITDA Margin % | B13: =IFERROR(B12/B4,0) -> 0.30551131 | C13: =IFERROR(C12/C4,0) -> 0.30175413 | D13: =IFERROR(D12/D4,0) -> 0.3061438 | E13: =IFERROR(E12/E4,0) -> 0.29351111 | F13: =IFERROR(F12/F4,0) -> 0.31501171 | G13: =IFERROR(G12/G4,0) -> 0.31780398 | H13: =IFERROR(H12/H4,0) -> 0.31944166 | I13: =IFERROR(I12/I4,0) -> 0.32247826 | ... AM13: =IFERROR(AM12/AM4,0) -> 0.32475156 | AN13: =AN12/AN4 -> 0.30759749

Sheet P&L- Detailed View
A1: Monthly P&L by Business Unit (₹m)
A2: Case Selected: | B2: =Assumptions!B3 -> Base
A3: Business Unit / Line Item | B3: 45658 | C3: 45689 | D3: 45717 | E3: 45748 | F3: 45778 | G3: 45809 | H3: 45839 | I3: 45870 | J3: 45901 | K3: 45931 | L3: 45962 | M3: 45992 | N3: 46023 | O3: 46054 | P3: 46082 | Q3: 46113 | R3: 46143 | S3: 46174 | T3: 46204 | U3: 46235 | V3: 46266 | W3: 46296 | X3: 46327 | Y3: 46357 | Z3: 46388 | AA3: 46419 | AB3: 46447 | AC3: 46478 | AD3: 46508 | AE3: 46539 | AF3: 46569 | AG3: 46600 | AH3: 46631 | AI3: 46661 | AJ3: 46692 | AK3: 46722
A4: Cloud Services — Revenue | B4: =SUMIFS(Actuals!$I$4:$I$123,Actuals!$D$4:$D$123,"Cloud Services",Actuals!$A$4:$A$123,B$3) -> 24.338836 | C4: 24.706962 | D4: 24.899863 | E4: 24.497568 | F4: 25.833514 | G4: 25.727615 | H4: 26.111648 | I4: 26.233833 | J4: 27.249722 | K4: 27.686496 | L4: 27.494707 | M4: 26.696697 | N4: 28.753731 | O4: 28.619838 | P4: 28.765513 | Q4: 28.341106 | R4: 29.325206 | S4: 29.758564 | T4: 30.332252 | U4: 30.640843 | V4: 31.195636 | W4: 31.649857 | X4: 31.615074 | Y4: 30.444454 | Z4: 35.114903 | AA4: 35.231953 | AB4: 35.349393 | AC4: 35.467224 | AD4: 35.585448 | AE4: 35.704067 | AF4: 35.82308 | AG4: 35.94249 | AH4: 36.062299 | AI4: 36.182506 | AJ4: 36.303115 | AK4: 36.424125
A5: Personnel Cost | B5: =SUMIFS(Actuals!$J$4:$J$123,Actuals!$D$4:$D$123,"Cloud Services",Actuals!$A$4:$A$123,B$3) -> 12.6 | C5: =SUMIFS(Actuals!$J$4:$J$123,Actuals!$D$4:$D$123,"Cloud Services",Actuals!$A$4:$A$123,C$3) -> 12.705 | D5: =SUMIFS(Actuals!$J$4:$J$123,Actuals!$D$4:$D$123,"Cloud Services",Actuals!$A$4:$A$123,D$3) -> 12.81 | E5: =SUMIFS(Actuals!$J$4:$J$123,Actuals!$D$4:$D$123,"Cloud Services",Actuals!$A$4:$A$123,E$3) -> 12.915 | F5: =SUMIFS(Actuals!$J$4:$J$123,Actuals!$D$4:$D$123,"Cloud Services",Actuals!$A$4:$A$123,F$3) -> 12.915 | G5: =SUMIFS(Actuals!$J$4:$J$123,Actuals!$D$4:$D$123,"Cloud Services",Actuals!$A$4:$A$123,G$3) -> 13.02 | H5: =SUMIFS(Actuals!$J$4:$J$123,Actuals!$D$4:$D$123,"Cloud Services",Actuals!$A$4:$A$123,H$3) -> 13.125 | I5: =SUMIFS(Actuals!$J$4:$J$123,Actuals!$D$4:$D$123,"Cloud Services",Actuals!$A$4:$A$123,I$3) -> 13.23 | ... Y5: =SUMIFS(Actuals!$J$4:$J$123,Actuals!$D$4:$D$123,"Cloud Services",Actuals!$A$4:$A$123,Y$3) -> 15.4707 | Z5: ='Headcount Plan'!K4 -> 17.704959 | AA5: ='Headcount Plan'!K9 -> 17.763976 | AB5: ='Headcount Plan'!K14 -> 17.823189 | AC5: ='Headcount Plan'!K19 -> 17.8826 | AD5: ='Headcount Plan'!K24 -> 17.942208 | AE5: ='Headcount Plan'!K29 -> 18.002016 | AF5: ='Headcount Plan'!K34 -> 18.062022 | AG5: ='Headcount Plan'!K39 -> 18.122229 | AH5: ='Headcount Plan'!K44 -> 18.182636 | AI5: ='Headcount Plan'!K49 -> 18.243245 | AJ5: ='Headcount Plan'!K54 -> 18.304056 | AK5: ='Headcount Plan'!K59 -> 18.36507 | AL5: =SUM(C5:M5) -> 144.48 | AM5: =SUM(N5:Y5) -> 179.8608 | AN5: =SUM(Z5:AK5) -> 216.39821
A6: Subcontractor Cost | B6: =SUMIFS(Actuals!$K$4:$K$123,Actuals!$D$4:$D$123,"Cloud Services",Actuals!$A$4:$A$123,B$3) -> 1.5820244 | C6: =SUMIFS(Actuals!$K$4:$K$123,Actuals!$D$4:$D$123,"Cloud Services",Actuals!$A$4:$A$123,C$3) -> 1.6059525 | D6: =SUMIFS(Actuals!$K$4:$K$123,Actuals!$D$4:$D$123,"Cloud Services",Actuals!$A$4:$A$123,D$3) -> 1.6184911 | E6: =SUMIFS(Actuals!$K$4:$K$123,Actuals!$D$4:$D$123,"Cloud Services",Actuals!$A$4:$A$123,E$3) -> 1.5923419 | F6: =SUMIFS(Actuals!$K$4:$K$123,Actuals!$D$4:$D$123,"Cloud Services",Actuals!$A$4:$A$123,F$3) -> 1.6791784 | G6: =SUMIFS(Actuals!$K$4:$K$123,Actuals!$D$4:$D$123,"Cloud Services",Actuals!$A$4:$A$123,G$3) -> 1.6722949 | H6: =SUMIFS(Actuals!$K$4:$K$123,Actuals!$D$4:$D$123,"Cloud Services",Actuals!$A$4:$A$123,H$3) -> 1.6972571 | I6: =SUMIFS(Actuals!$K$4:$K$123,Actuals!$D$4:$D$123,"Cloud Services",Actuals!$A$4:$A$123,I$3) -> 1.7051991 | ... Y6: =SUMIFS(Actuals!$K$4:$K$123,Actuals!$D$4:$D$123,"Cloud Services",Actuals!$A$4:$A$123,Y$3) -> 1.9788895 | Z6: =Z4*Assumptions!$B$23 -> 2.6336178 | AA6: =AA4*Assumptions!$B$23 -> 2.6423965 | AB6: =AB4*Assumptions!$B$23 -> 2.6512045 | AC6: =AC4*Assumptions!$B$23 -> 2.6600418 | AD6: =AD4*Assumptions!$B$23 -> 2.6689086 | AE6: =AE4*Assumptions!$B$23 -> 2.677805 | AF6: =AF4*Assumptions!$B$23 -> 2.686731 | AG6: =AG4*Assumptions!$B$23 -> 2.6956868 | ... AK6: =AK4*Assumptions!$B$23 -> 2.7318094 | AL6: =SUM(C6:M6) -> 18.664011 | AM6: =SUM(N6:Y6) -> 23.363735 | AN6: =SUM(Z6:AK6) -> 32.189295
A7: Gross Profit | B7: =B4-B5-B6 -> 10.156812 | C7: =C4-C5-C6 -> 10.396009 | D7: =D4-D5-D6 -> 10.471372 | E7: =E4-E5-E6 -> 9.9902262 | F7: =F4-F5-F6 -> 11.239336 | G7: =G4-G5-G6 -> 11.03532 | H7: =H4-H5-H6 -> 11.289391 | I7: =I4-I5-I6 -> 11.298633 | ... AK7: =AK4-AK5-AK6 -> 15.327246 | AL7: =SUM(C7:M7) -> 123.99461 | AM7: =SUM(N7:Y7) -> 156.21754 | AN7: =SUM(Z7:AK7) -> 180.6031
A8: Gross Margin % | B8: =IFERROR(B7/B4,0) -> 0.41730886 | C8: =IFERROR(C7/C4,0) -> 0.42077247 | D8: =IFERROR(D7/D4,0) -> 0.42053933 | E8: =IFERROR(E7/E4,0) -> 0.40780481 | F8: =IFERROR(F7/F4,0) -> 0.43506801 | G8: =IFERROR(G7/G4,0) -> 0.42892899 | H8: =IFERROR(H7/H4,0) -> 0.43235076 | I8: =IFERROR(I7/I4,0) -> 0.43068939 | ... AK8: =IFERROR(AK7/AK4,0) -> 0.42079929 | AL8: =SUM(C8:M8) -> 4.7451683 | AM8: =SUM(N8:Y8) -> 5.2109036 | AN8: =SUM(Z8:AK8) -> 5.0495915
A9: Software Cost | B9: =SUMIFS(Actuals!$L$4:$L$123,Actuals!$D$4:$D$123,"Cloud Services",Actuals!$A$4:$A$123,B$3) -> 1.08 | C9: =SUMIFS(Actuals!$L$4:$L$123,Actuals!$D$4:$D$123,"Cloud Services",Actuals!$A$4:$A$123,C$3) -> 1.089 | D9: =SUMIFS(Actuals!$L$4:$L$123,Actuals!$D$4:$D$123,"Cloud Services",Actuals!$A$4:$A$123,D$3) -> 1.098 | E9: =SUMIFS(Actuals!$L$4:$L$123,Actuals!$D$4:$D$123,"Cloud Services",Actuals!$A$4:$A$123,E$3) -> 1.107 | F9: =SUMIFS(Actuals!$L$4:$L$123,Actuals!$D$4:$D$123,"Cloud Services",Actuals!$A$4:$A$123,F$3) -> 1.107 | G9: =SUMIFS(Actuals!$L$4:$L$123,Actuals!$D$4:$D$123,"Cloud Services",Actuals!$A$4:$A$123,G$3) -> 1.116 | H9: =SUMIFS(Actuals!$L$4:$L$123,Actuals!$D$4:$D$123,"Cloud Services",Actuals!$A$4:$A$123,H$3) -> 1.125 | I9: =SUMIFS(Actuals!$L$4:$L$123,Actuals!$D$4:$D$123,"Cloud Services",Actuals!$A$4:$A$123,I$3) -> 1.134 | ... Y9: =SUMIFS(Actuals!$L$4:$L$123,Actuals!$D$4:$D$123,"Cloud Services",Actuals!$A$4:$A$123,Y$3) -> 1.31355 | Z9: ='Headcount Plan'!G4*Assumptions!G13*(1+Assumptions!$B$9) -> 1.5250375 | AA9: ='Headcount Plan'!G9*Assumptions!G13*(1+Assumptions!$B$9) -> 1.530121 | AB9: ='Headcount Plan'!G14*Assumptions!G13*(1+Assumptions!$B$9) -> 1.5352214 | AC9: ='Headcount Plan'!G19*Assumptions!G13*(1+Assumptions!$B$9) -> 1.5403388 | AD9: ='Headcount Plan'!G24*Assumptions!G13*(1+Assumptions!$B$9) -> 1.5454732 | AE9: ='Headcount Plan'!G29*Assumptions!G13*(1+Assumptions!$B$9) -> 1.5506248 | AF9: ='Headcount Plan'!G34*Assumptions!G13*(1+Assumptions!$B$9) -> 1.5557936 | AG9: ='Headcount Plan'!G39*Assumptions!G13*(1+Assumptions!$B$9) -> 1.5609795 | AH9: ='Headcount Plan'!G44*Assumptions!G13*(1+Assumptions!$B$9) -> 1.5661828 | AI9: ='Headcount Plan'!G49*Assumptions!G13*(1+Assumptions!$B$9) -> 1.5714034 | AJ9: ='Headcount Plan'!G54*Assumptions!G13*(1+Assumptions!$B$9) -> 1.5766414 | AK9: ='Headcount Plan'!G59*Assumptions!G13*(1+Assumptions!$B$9) -> 1.5818969 | AL9: =SUM(C9:M9) -> 12.384 | AM9: =SUM(N9:Y9) -> 15.2712 | AN9: =SUM(Z9:AK9) -> 18.639714
